<?xml version="1.0"?>
<sdf version="1.6">
  <model name="euler_drone">
    <static>false</static>
    
    <link name="base_link">
      <pose>0 0 0.1 0 0 0</pose>
      <inertial>
        <mass>1.5</mass>
        <inertia>
          <ixx>0.029</ixx><ixy>0</ixy><ixz>0</ixz>
          <iyy>0.029</iyy><iyz>0</iyz>
          <izz>0.055</izz>
        </inertia>
      </inertial>
      
      <collision name="body_collision">
        <geometry>
          <box><size>0.4 0.4 0.1</size></box>
        </geometry>
      </collision>
      
      <visual name="body_visual">
        <geometry>
          <box><size>0.4 0.4 0.1</size></box>
        </geometry>
        <material>
          <ambient>0.2 0.2 0.8 1</ambient>
          <diffuse>0.2 0.2 0.8 1</diffuse>
        </material>
      </visual>
      
      <sensor name="imu" type="imu">
        <always_on>true</always_on>
        <update_rate>100</update_rate>
        <imu>
          <angular_velocity>
            <x><noise type="gaussian"><mean>0</mean><stddev>0.01</stddev></noise></x>
            <y><noise type="gaussian"><mean>0</mean><stddev>0.01</stddev></noise></y>
            <z><noise type="gaussian"><mean>0</mean><stddev>0.01</stddev></noise></z>
          </angular_velocity>
          <linear_acceleration>
            <x><noise type="gaussian"><mean>0</mean><stddev>0.1</stddev></noise></x>
            <y><noise type="gaussian"><mean>0</mean><stddev>0.1</stddev></noise></y>
            <z><noise type="gaussian"><mean>0</mean><stddev>0.1</stddev></noise></z>
          </linear_acceleration>
        </imu>
      </sensor>
      
      <sensor name="gps" type="gps">
        <always_on>true</always_on>
        <update_rate>10</update_rate>
        <gps>
          <position_sensing>
            <horizontal><noise type="gaussian"><mean>0</mean><stddev>0.5</stddev></noise></horizontal>
            <vertical><noise type="gaussian"><mean>0</mean><stddev>1.0</stddev></noise></vertical>
          </position_sensing>
        </gps>
      </sensor>
    </link>
    
    <link name="rotor_0">
      <pose>0.15 0.15 0.15 0 0 0</pose>
      <inertial><mass>0.02</mass></inertial>
      <visual name="rotor_visual">
        <geometry><cylinder><radius>0.1</radius><length>0.01</length></cylinder></geometry>
        <material><ambient>0.1 0.1 0.1 1</ambient></material>
      </visual>
    </link>
    <joint name="rotor_0_joint" type="revolute">
      <parent>base_link</parent><child>rotor_0</child>
      <axis><xyz>0 0 1</xyz></axis>
    </joint>
    
    <link name="rotor_1">
      <pose>-0.15 0.15 0.15 0 0 0</pose>
      <inertial><mass>0.02</mass></inertial>
      <visual name="rotor_visual">
        <geometry><cylinder><radius>0.1</radius><length>0.01</length></cylinder></geometry>
        <material><ambient>0.1 0.1 0.1 1</ambient></material>
      </visual>
    </link>
    <joint name="rotor_1_joint" type="revolute">
      <parent>base_link</parent><child>rotor_1</child>
      <axis><xyz>0 0 1</xyz></axis>
    </joint>
    
    <link name="rotor_2">
      <pose>-0.15 -0.15 0.15 0 0 0</pose>
      <inertial><mass>0.02</mass></inertial>
      <visual name="rotor_visual">
        <geometry><cylinder><radius>0.1</radius><length>0.01</length></cylinder></geometry>
        <material><ambient>0.1 0.1 0.1 1</ambient></material>
      </visual>
    </link>
    <joint name="rotor_2_joint" type="revolute">
      <parent>base_link</parent><child>rotor_2</child>
      <axis><xyz>0 0 1</xyz></axis>
    </joint>
    
    <link name="rotor_3">
      <pose>0.15 -0.15 0.15 0 0 0</pose>
      <inertial><mass>0.02</mass></inertial>
      <visual name="rotor_visual">
        <geometry><cylinder><radius>0.1</radius><length>0.01</length></cylinder></geometry>
        <material><ambient>0.1 0.1 0.1 1</ambient></material>
      </visual>
    </link>
    <joint name="rotor_3_joint" type="revolute">
      <parent>base_link</parent><child>rotor_3</child>
      <axis><xyz>0 0 1</xyz></axis>
    </joint>
    
    <plugin name="euler_swarm_plugin" filename="libeuler_gazebo_plugin.so">
      <drone_id>0</drone_id>
      <broadcast_port>15560</broadcast_port>
      <update_rate>10</update_rate>
    </plugin>
  </model>
</sdf>

